2017-07-31 23:35:14,243 golem INFO Test execution started: project.create_page
2017-07-31 23:35:14,245 golem INFO Driver: firefox
2017-07-31 23:35:21,385 golem INFO Take screenshot error
2017-07-31 23:35:21,609 golem ERROR An error ocurred:
Traceback (most recent call last):
  File "/Users/lucianofeo/Desktop/golem/src/golem/test_runner/test_runner.py", line 77, in run_test
    test_module.setup(golem.core.test_data)
  File "/Users/lucianofeo/Desktop/golem/src/examples/projects/golem/tests/project/create_page.py", line 9, in setup
    go_to('http://localhost:8000/')
  File "/Users/lucianofeo/Desktop/golem/src/golem/core/actions.py", line 113, in go_to
    driver.get(url)
  File "/Users/lucianofeo/Desktop/golem/env/lib/python3.6/site-packages/selenium/webdriver/remote/webdriver.py", line 269, in get
    self.execute(Command.GET, {'url': url})
  File "/Users/lucianofeo/Desktop/golem/env/lib/python3.6/site-packages/selenium/webdriver/remote/webdriver.py", line 257, in execute
    self.error_handler.check_response(response)
  File "/Users/lucianofeo/Desktop/golem/env/lib/python3.6/site-packages/selenium/webdriver/remote/errorhandler.py", line 194, in check_response
    raise exception_class(message, screen, stacktrace)
selenium.common.exceptions.WebDriverException: Message: Error loading page

2017-07-31 23:35:21,612 golem INFO Close driver
