2017-07-31 23:35:08,241 golem INFO Test execution started: index.create_project_missing_name
2017-07-31 23:35:08,242 golem INFO Driver: firefox
2017-07-31 23:35:13,755 golem INFO Take screenshot error
2017-07-31 23:35:13,981 golem ERROR An error ocurred:
Traceback (most recent call last):
  File "/Users/lucianofeo/Desktop/golem/src/golem/test_runner/test_runner.py", line 77, in run_test
    test_module.setup(golem.core.test_data)
  File "/Users/lucianofeo/Desktop/golem/src/examples/projects/golem/tests/index/create_project_missing_name.py", line 8, in setup
    go_to('http://localhost:8000/')
  File "/Users/lucianofeo/Desktop/golem/src/golem/core/actions.py", line 113, in go_to
    driver.get(url)
  File "/Users/lucianofeo/Desktop/golem/env/lib/python3.6/site-packages/selenium/webdriver/remote/webdriver.py", line 269, in get
    self.execute(Command.GET, {'url': url})
  File "/Users/lucianofeo/Desktop/golem/env/lib/python3.6/site-packages/selenium/webdriver/remote/webdriver.py", line 257, in execute
    self.error_handler.check_response(response)
  File "/Users/lucianofeo/Desktop/golem/env/lib/python3.6/site-packages/selenium/webdriver/remote/errorhandler.py", line 194, in check_response
    raise exception_class(message, screen, stacktrace)
selenium.common.exceptions.WebDriverException: Message: Error loading page

2017-07-31 23:35:13,982 golem INFO Close driver
2017-07-31 23:35:14,145 golem INFO Test execution started: login.login_missing_password
2017-07-31 23:35:14,145 golem INFO Driver: firefox
2017-07-31 23:35:21,264 golem INFO Take screenshot error
2017-07-31 23:35:21,572 golem ERROR An error ocurred:
Traceback (most recent call last):
  File "/Users/lucianofeo/Desktop/golem/src/golem/test_runner/test_runner.py", line 82, in run_test
    test_module.test(golem.core.test_data)
  File "/Users/lucianofeo/Desktop/golem/src/examples/projects/golem/tests/login/login_missing_password.py", line 10, in test
    go_to('http://localhost:8000/')
  File "/Users/lucianofeo/Desktop/golem/src/golem/core/actions.py", line 113, in go_to
    driver.get(url)
  File "/Users/lucianofeo/Desktop/golem/env/lib/python3.6/site-packages/selenium/webdriver/remote/webdriver.py", line 269, in get
    self.execute(Command.GET, {'url': url})
  File "/Users/lucianofeo/Desktop/golem/env/lib/python3.6/site-packages/selenium/webdriver/remote/webdriver.py", line 257, in execute
    self.error_handler.check_response(response)
  File "/Users/lucianofeo/Desktop/golem/env/lib/python3.6/site-packages/selenium/webdriver/remote/errorhandler.py", line 194, in check_response
    raise exception_class(message, screen, stacktrace)
selenium.common.exceptions.WebDriverException: Message: Error loading page

2017-07-31 23:35:21,574 golem INFO Close driver
