23:35:14.220 INFO Test execution started: login.login_missing_username
23:35:14.222 INFO Driver: firefox
23:35:21.134 INFO Take screenshot error
23:35:21.423 ERROR An error ocurred:
Traceback (most recent call last):
  File "/Users/lucianofeo/Desktop/golem/src/golem/test_runner/test_runner.py", line 82, in run_test
    test_module.test(golem.core.test_data)
  File "/Users/lucianofeo/Desktop/golem/src/examples/projects/golem/tests/login/login_missing_username.py", line 10, in test
    go_to('http://localhost:8000/')
  File "/Users/lucianofeo/Desktop/golem/src/golem/core/actions.py", line 113, in go_to
    driver.get(url)
  File "/Users/lucianofeo/Desktop/golem/env/lib/python3.6/site-packages/selenium/webdriver/remote/webdriver.py", line 269, in get
    self.execute(Command.GET, {'url': url})
  File "/Users/lucianofeo/Desktop/golem/env/lib/python3.6/site-packages/selenium/webdriver/remote/webdriver.py", line 257, in execute
    self.error_handler.check_response(response)
  File "/Users/lucianofeo/Desktop/golem/env/lib/python3.6/site-packages/selenium/webdriver/remote/errorhandler.py", line 194, in check_response
    raise exception_class(message, screen, stacktrace)
selenium.common.exceptions.WebDriverException: Message: Error loading page

23:35:21.426 INFO Close driver
